Workbook

Sheet 00 Read Me
A1: ExamPrep AI — Student Evaluation Platform
A2: Module-wise Construction Blueprint | Version 1.4 | 05 Sep 2026 | 17 tabs, 122 features
A4: What this workbook is
A5: A build plan, not code. It converts the ExamPrep AI tutor specification (paper generation, uploaded-paper evaluation, concept tracking, remediation, weekly summaries) plus the existing Grok prototype into 22 buildable modules with features, data model, APIs, screens, AI functions, effort and a phased roadmap.
A7: Source material behind the plan
A8: 1. The ExamPrep AI role specification (7 sections: paper generation, evaluation protocol, concept tracking, session memory, teaching rules, weekly summary, final directive).
A9: 2. The uploaded Grok prototype (grok-workspace.zip): TanStack Start + React 19 + Tailwind v4 + shadcn/ui, better-auth, Postgres (Neon) / PGlite via Kysely, Zustand persist, deployed on Vercel. It ships a hardcoded Class-7 NCERT Ganita Prakash curriculum (15 chapters), ~75 questions, a mastery engine, and practice / exam / learn / mastery routes.
A10: 3. The live coaching project's diagnostic framework: Actual Score vs Knowledge Score, Delivery Gap, error patterns P1-P6, presentation habits H1-H10.
A12: How to use each tab
A13: 01 Product Scope | B13: In scope / out of scope / personas / success metrics. Agree this first — it is the contract for everything below.
A14: 02 Module Master | B14: The 22 modules. Effort, feature count and % complete auto-roll from tab 03. This is your weekly status page.
A15: 03 Feature Backlog | B15: 111 features with user story, acceptance criteria, effort and sprint. This is what you hand to a developer or to Claude Code, one row at a time.
A16: 04 Data Model | B16: 26 tables with key columns and relations. Build this before any UI.
A17: 05 API Endpoints | B17: 38 routes with auth level and payload shape.
A18: 06 Screens & Routes | B18: 24 screens mapped to modules and roles.
A19: 07 AI Layer | B19: 12 AI functions with model choice, prompt inputs, output contract, guardrails and fallback. The riskiest and most valuable tab.
A20: 08 Gap Analysis | B20: What the Grok prototype already gives you vs what must be built. Reuse column tells you what to keep.
A21: 09 Tech Stack | B21: Locked technology decisions with rationale and alternatives rejected.
A22: 10 Roadmap | B22: 5 phases with dates driven from the Project Start Date cell. Change that one cell and all dates move.
A23: 11 Risks | B23: 14 risks scored by probability x impact with owner and mitigation.
A24: 12 QA & Test Plan | B24: 22 test scenarios by module, including the accuracy tests that matter most (OCR, AI grading, Telugu script).
A25: 13 Effort Summary | B25: Rolled-up effort by phase and priority, converted to calendar weeks using the velocity assumptions at the top.
A27: Legend
A28: Blue text | B28: An input you can change. All other cells are text or formulas.
A29: Yellow fill | B29: Key assumption. Verify before committing to a date.
A30: Priority | B30: P0 = MVP blocker. P1 = needed for a usable v1. P2 = valuable. P3 = later / optional.
A31: Status | B31: Not Started / In Progress / Blocked / Done. Type it in column J of tab 03; tab 02 and 13 recalculate.
A32: Effort | B32: Person-days for one mid-level full-stack developer working with an AI coding assistant. Estimates, not quotes.
A34: Decisions still open (answer before Phase 1 starts)
A35: 1. Single-family tool or multi-tenant product? | B35: Changes M02, M20 and M21 substantially. Plan currently assumes: build single-family first, keep the schema multi-tenant-ready.
A36: 2. Which subjects at launch? | B36: Plan assumes Maths + Science in Phase 1, Social + Telugu in Phase 2. Telugu carries font, script and grammar-tagging cost (M18).
A37: 3. Handwritten evaluation: photo upload or typed transcription? | B37: Photo + vision OCR (M10) is the honest answer but the least reliable. Plan keeps typed fallback always available.
A38: 4. Does the student attempt papers on screen, or on paper then upload? | B38: Plan supports both. On-screen (M08) is cheaper and auto-scored; paper-then-upload (M10) is what actually reflects exam conditions.
A39: 5. Board coverage: CBSE only, or CBSE + AP/TS State? | B39: Affects M04 blueprint engine. Plan assumes CBSE-style blueprints first, State Board added as a blueprint record, not new code.

Sheet 01 Product Scope
A1: 01 Product Scope, Personas and Success Metrics
A3: Category | B3: Item | C3: Detail | D3: Status / Priority
A4: Vision | B4: One sentence | C4: A web app that generates syllabus-exact question papers, evaluates the student's attempt question-by-question, diagnoses whether each lost mark is a knowledge gap or a delivery habit, and tracks every concept until it is mastered. | D4: Agreed
A5: Primary persona | B5: Parent / coach | C5: Sets up the child, requests papers, uploads the written attempt, reads the diagnosis, receives one concrete action per session. Not a teacher; needs plain language. | D5: Agreed
A6: Secondary persona | B6: Student (Class 6-10) | C6: Takes practice sets and timed mocks on screen, sees mastery rings and remediation drills. Must never feel graded harshly in tone. | D6: Agreed
A7: Tertiary persona | B7: Tutor / school teacher | C7: Multi-student console, bulk paper generation, class-level weak-concept heatmap. Phase 4. | D7: Deferred
A8: In scope | B8: Paper generation | C8: Blueprint-driven papers per subject/chapter/marks/duration, with sections A-D, Bloom distribution, concept tags, answer key, marking scheme, concept coverage table, printable A4 PDF. | D8: P0
A9: In scope | B9: Attempt capture | C9: On-screen attempt (auto-scored) AND photo/scan upload of a handwritten attempt (AI-assisted evaluation with human confirm). | D9: P0/P1
A10: In scope | B10: Evaluation | C10: Per-question marks, error classification, Actual vs Knowledge score, Delivery Gap, habit observations. | D10: P0
A11: In scope | B11: Tracking | C11: Cumulative concept tracker with trend arrows, priority flag rules, auto-generated mini revision tests, weekly summary. | D11: P0
A12: In scope | B12: Remediation | C12: 4-step protocol per weak concept: refresher, 2 solved examples, 3 practice questions, upload-and-evaluate loop. | D12: P1
A13: In scope | B13: Subjects | C13: Maths and Science at launch; Social Studies and Telugu in Phase 2 (Telugu needs script + grammar tagging). | D13: P0/P1
A14: Out of scope v1 | B14: Live video tutoring | C14: No synchronous teaching, no video calls. | D14: Excluded
... A26: Constraint | B26: Offline reality | C26: The printed PDF is the primary artefact. The app must remain useful for a family that prints, writes by hand and uploads photos. | D26: Design rule

Sheet 02 Module Master
A1: 02 Module Master — counts and effort roll up automatically from tab 03
A3: Module ID | B3: Module | C3: Phase | D3: Purpose | E3: Key Deliverable | F3: Depends On | G3: Priority | H3: Notes / Reuse | I3: Features | J3: Est. Days | K3: Done | L3: % Complete
A4: M01 | B4: Foundation & Infrastructure | C4: P0 Foundation | D4: Repo, environments, CI, Vercel projects, error tracking, secrets. | E4: Deployable skeleton with preview + prod environments | F4: - | G4: P0 | H4: Reuse Grok scaffold heavily | I4: =COUNTIF('03 Feature Backlog'!$A:$A,$A4) | J4: =SUMIF('03 Feature Backlog'!$A:$A,$A4,'03 Feature Backlog'!$H:$H) | K4: =COUNTIFS('03 Feature Backlog'!$A:$A,$A4,'03 Feature Backlog'!$J:$J,"Done") | L4: =IFERROR(K4/I4,0)
A5: M02 | B5: Auth, Roles & Household | C5: P0 Foundation | D5: Sign-in, parent/student/admin roles, one household with many students. | E5: Role-gated routing and student switching | F5: M01 | G5: P0 | H5: better-auth already wired in prototype | I5: =COUNTIF('03 Feature Backlog'!$A:$A,$A5) | J5: =SUMIF('03 Feature Backlog'!$A:$A,$A5,'03 Feature Backlog'!$H:$H) | K5: =COUNTIFS('03 Feature Backlog'!$A:$A,$A5,'03 Feature Backlog'!$J:$J,"Done") | L5: =IFERROR(K5/I5,0)
A6: M03 | B6: Database & Migrations | C6: P0 Foundation | D6: Postgres schema, migration runner, seed scripts, backup policy. | E6: Versioned schema covering all 26 tables | F6: M01 | G6: P0 | H6: Prototype has Kysely + migration script | I6: =COUNTIF('03 Feature Backlog'!$A:$A,$A6) | J6: =SUMIF('03 Feature Backlog'!$A:$A,$A6,'03 Feature Backlog'!$H:$H) | K6: =COUNTIFS('03 Feature Backlog'!$A:$A,$A6,'03 Feature Backlog'!$J:$J,"Done") | L6: =IFERROR(K6/I6,0)
A7: M04 | B7: Curriculum & Syllabus Engine | C7: P1 Core | D7: Board > class > subject > chapter > concept hierarchy with explicit in-scope and out-of-scope text per chapter. | E7: Admin-editable syllabus tree with scope guards | F7: M03 | G7: P0 | H7: Prototype hardcodes this in TypeScript — must move to DB | I7: =COUNTIF('03 Feature Backlog'!$A:$A,$A7) | J7: =SUMIF('03 Feature Backlog'!$A:$A,$A7,'03 Feature Backlog'!$H:$H) | K7: =COUNTIFS('03 Feature Backlog'!$A:$A,$A7,'03 Feature Backlog'!$J:$J,"Done") | L7: =IFERROR(K7/I7,0)
A8: M05 | B8: Question Bank | C8: P1 Core | D8: Questions with concept, Bloom, difficulty, marks, type, options, answer, hint, step-marks, diagram, language. | E8: CRUD + bulk import + duplicate detection | F8: M04 | G8: P0 | H8: 75 seed questions exist | I8: =COUNTIF('03 Feature Backlog'!$A:$A,$A8) | J8: =SUMIF('03 Feature Backlog'!$A:$A,$A8,'03 Feature Backlog'!$H:$H) | K8: =COUNTIFS('03 Feature Backlog'!$A:$A,$A8,'03 Feature Backlog'!$J:$J,"Done") | L8: =IFERROR(K8/I8,0)
A9: M06 | B9: Paper Blueprint & Generator | C9: P1 Core | D9: Blueprint records (sections, marks, counts, Bloom mix, choice rules) + weighted selection 40/40/20 from the mastery log. | E9: One-click paper honouring blueprint and weak-concept weighting | F9: M05, M12 | G9: P0 | H9: Core differentiator — nothing in prototype | I9: =COUNTIF('03 Feature Backlog'!$A:$A,$A9) | J9: =SUMIF('03 Feature Backlog'!$A:$A,$A9,'03 Feature Backlog'!$H:$H) | K9: =COUNTIFS('03 Feature Backlog'!$A:$A,$A9,'03 Feature Backlog'!$J:$J,"Done") | L9: =IFERROR(K9/I9,0)
A10: M07 | B10: Paper Rendering & Export | C10: P1 Core | D10: Themed HTML + print-ready A4 PDF with rough-work column, answer key, marking scheme, concept coverage table. | E10: PDF identical to school paper format | F10: M06 | G10: P0 | H10: Server-side PDF; template engine needed | I10: =COUNTIF('03 Feature Backlog'!$A:$A,$A10) | J10: =SUMIF('03 Feature Backlog'!$A:$A,$A10,'03 Feature Backlog'!$H:$H) | K10: =COUNTIFS('03 Feature Backlog'!$A:$A,$A10,'03 Feature Backlog'!$J:$J,"Done") | L10: =IFERROR(K10/I10,0)
A11: M08 | B11: Online Test Engine | C11: P1 Core | D11: Timed on-screen attempt, autosave, resume, section navigation, review-before-submit. | E11: Attempt captured with per-question timing | F11: M05 | G11: P0 | H11: Prototype has a basic exam.take flow | I11: =COUNTIF('03 Feature Backlog'!$A:$A,$A11) | J11: =SUMIF('03 Feature Backlog'!$A:$A,$A11,'03 Feature Backlog'!$H:$H) | K11: =COUNTIFS('03 Feature Backlog'!$A:$A,$A11,'03 Feature Backlog'!$J:$J,"Done") | L11: =IFERROR(K11/I11,0)
A12: M09 | B12: Auto-Evaluation Engine | C12: P1 Core | D12: Objective auto-scoring, subjective rubric scoring with AI, step-mark allocation, human override. | E12: Marks + error type per question, always overridable | F12: M08 | G12: P0 | H12: Prototype scores MCQ/fill only | I12: =COUNTIF('03 Feature Backlog'!$A:$A,$A12) | J12: =SUMIF('03 Feature Backlog'!$A:$A,$A12,'03 Feature Backlog'!$H:$H) | K12: =COUNTIFS('03 Feature Backlog'!$A:$A,$A12,'03 Feature Backlog'!$J:$J,"Done") | L12: =IFERROR(K12/I12,0)
A13: M10 | B13: Upload & Handwriting OCR | C13: P2 Diagnostics | D13: Photo/PDF upload of written attempt, page-to-question mapping, vision extraction, ambiguity flagging. | E13: Handwritten paper converted to reviewable answers | F13: M09 | G13: P1 | H13: Highest technical risk | I13: =COUNTIF('03 Feature Backlog'!$A:$A,$A13) | J13: =SUMIF('03 Feature Backlog'!$A:$A,$A13,'03 Feature Backlog'!$H:$H) | K13: =COUNTIFS('03 Feature Backlog'!$A:$A,$A13,'03 Feature Backlog'!$J:$J,"Done") | L13: =IFERROR(K13/I13,0)
A14: M11 | B14: Diagnostic Engine | C14: P2 Diagnostics | D14: Actual vs Knowledge score, Delivery Gap, error patterns P1-P6, presentation habits H1-H10. | E14: Diagnosis report per paper | F14: M09 | G14: P0 | H14: The intellectual heart of the product | I14: =COUNTIF('03 Feature Backlog'!$A:$A,$A14) | J14: =SUMIF('03 Feature Backlog'!$A:$A,$A14,'03 Feature Backlog'!$H:$H) | K14: =COUNTIFS('03 Feature Backlog'!$A:$A,$A14,'03 Feature Backlog'!$J:$J,"Done") | L14: =IFERROR(K14/I14,0)
A15: M12 | B15: Concept Tracker & Mastery | C15: P1 Core | D15: Running per-concept log, trend arrows, priority flag rules, maintenance/retire rules. | E15: Cumulative tracker driving paper weighting | F15: M09 | G15: P0 | H15: Prototype mastery engine is a good base | I15: =COUNTIF('03 Feature Backlog'!$A:$A,$A15) | J15: =SUMIF('03 Feature Backlog'!$A:$A,$A15,'03 Feature Backlog'!$H:$H) | K15: =COUNTIFS('03 Feature Backlog'!$A:$A,$A15,'03 Feature Backlog'!$J:$J,"Done") | L15: =IFERROR(K15/I15,0)
... A25: M22 | B25: QA, Testing & Launch | C25: P4 Hardening | D25: Unit/integration/E2E, AI accuracy harness, UAT with real papers, launch checklist. | E25: Green suite + 20-paper accuracy benchmark | F25: All | G25: P0 | H25: Accuracy harness is non-negotiable | I25: =COUNTIF('03 Feature Backlog'!$A:$A,$A25) | J25: =SUMIF('03 Feature Backlog'!$A:$A,$A25,'03 Feature Backlog'!$H:$H) | K25: =COUNTIFS('03 Feature Backlog'!$A:$A,$A25,'03 Feature Backlog'!$J:$J,"Done") | L25: =IFERROR(K25/I25,0)
H26: TOTAL | I26: =SUM(I4:I25) | J26: =SUM(J4:J25) | K26: =SUM(K4:K25) | L26: =IFERROR(K26/I26,0)

Sheet 03 Feature Backlog
A1: 03 Feature Backlog — 132 features. Type Not Started / In Progress / Blocked / Done in column J.
A3: Module ID | B3: Feature ID | C3: Feature | D3: User Story | E3: Acceptance Criteria | F3: Priority | G3: Complexity | H3: Est. Days | I3: Sprint | J3: Status | K3: Notes
A4: M01 | B4: F001 | C4: Repo & monorepo setup | D4: As a developer I want a clean repo so that work is versioned and reviewable. | E4: Repo initialised, branch protection on main, PR template, conventional commits, README with local setup that works from a cold clone. | F4: P0 | G4: S | H4: 1 | I4: S1 | J4: Done | K4: Repo initialised, PR template + conventional-commit convention in place. GitHub remote set up (sathyaantham2-wq/examprep-ai-, pushed 2026-09-16). Branch protection on main now requires the Vercel status check to pass before merge (see F003).
A5: M01 | B5: F002 | C5: Environment & secrets management | D5: As a developer I want typed env vars so that misconfiguration fails loudly at boot. | E5: Zod-validated env schema; app refuses to start on missing keys; .env.example committed; secrets stored in Vercel, never in git. | F5: P0 | G5: S | H5: 1 | I5: S1 | J5: Done | K5: src/lib/env.ts: a single Zod schema for every env var actually read anywhere in the codebase (DATABASE_URL, BETTER_AUTH_SECRET/URL required; GOOGLE_CLIENT_ID/SECRET and ANTHROPIC_API_KEY optional, matching their documented graceful-degradation paths). Replaced every scattered process.env.X read (connection.ts, auth-pool.ts, auth.ts, ai-grading.ts) with this validated object. Verified live: booting with BETTER_AUTH_SECRET removed throws immediately with the exact missing key named, not a confusing failure deep in a request; booting normally still works, confirmed via a live dev-server request. .env.example already existed and now documents ANTHROPIC_API_KEY too. "Secrets stored in Vercel, never in git" -- .env is already gitignored (verified back in F001) and no secret has been committed at any point this project.
A6: M01 | B6: F003 | C6: Vercel preview + production pipeline | D6: As a team I want every PR to deploy a preview so that changes are reviewed live. | E6: PR opens a preview URL; main deploys to production; build fails block merge. | F6: P0 | G6: S | H6: 1 | I6: S1 | J6: Done | K6: Repo pushed to GitHub (sathyaantham2-wq/examprep-ai-) and connected to Vercel. Verified live: push to main deploys production, a real PR (#1) produced a real preview URL and merged cleanly. Branch protection on main now requires the examprep-ai Vercel check to pass before merge (set up 2026-09-16). One loose end, not blocking: a duplicate Vercel project (examprep-ai-, trailing hyphen) still exists from setup -- harmless (both point at the same repo/commits) but should be deleted via the Vercel dashboard when convenient; no delete capability was available via the connected Vercel MCP connector to do it directly.
A7: M01 | B7: F004 | C7: Error tracking & structured logging | D7: As a developer I want server errors captured so that failures are not silent. | E7: Sentry (or equivalent) capturing client + server errors with release tagging; request-scoped log IDs. | F7: P1 | G7: S | H7: 1 | I7: S2 | J7: Done | K7: No Sentry/error-tracking account exists in this dev environment, so error_log (migration 0060) is a self-hosted equivalent, wired the same way Sentry would be. Server: every route handler wrapped via wrapRouteHandlers() -- catches unhandled exceptions, writes one error_log row with a request-scoped UUID (request_id), echoes the same id back in the response header and body. Client: root error boundary (__root.tsx) + a window.onerror/unhandledrejection listener POST the same shape to the new public POST /api/errors route. release column tagged from VERCEL_GIT_COMMIT_SHA (set automatically by Vercel per deploy) -- Vercel-set env var added to env.ts. Verified: 8 unit/integration tests (error-log.test.ts, error-log.integration.test.ts) plus a full-suite regression run (376 tests, 66 files, all green) confirming the mechanical wrapRouteHandlers() rollout across all 65+ route files changed no existing route behaviour. Committed 8399dbb.
A8: M01 | B8: F005 | C8: Design system & theming | D8: As a user I want a consistent interface so that the app feels coherent. | E8: shadcn/ui + Tailwind tokens, light/dark, typography scale, print stylesheet defined once. | F8: P1 | G8: M | H8: 2 | I8: S2 | J8: In Progress | K8: shadcn/ui is now actually wired in (components.json was configured but nothing had been added yet) -- hand-written Button (5 variants: default/destructive/outline/secondary/ghost/link, 4 sizes) and Card (+ Header/Title/Description/Content/Footer) primitives now live at src/components/ui/, matching the existing "new-york" style config and using the pre-existing cn() helper. A ThemeProvider (next-themes, class-based, system-aware, SSR-safe via suppressHydrationWarning) wraps the whole app in __root.tsx, plus a working ThemeToggle component. A typography scale (.text-display/.text-h1/.text-h2/.text-h3/.text-body/.text-small/.text-caption) is defined once in src/styles.css for every future screen to reuse instead of ad-hoc text-* sizes. A print stylesheet (@media print) flattens colors to black-on-white, drops anything marked .no-print, and cleans up card borders/shadows for printouts -- this covers screens a parent might Ctrl+P directly (e.g. a report page), separate from the existing server-side Playwright PDF pipeline used for generated papers/reports. Also removed roughly 180 lines of dead, unreferenced "ocean/island" decorative CSS (sea-ink/lagoon/palm color variables, island-shell, feature-card, nav-link, site-footer classes) that had been sitting in styles.css since the initial scaffold but were never used by any actual component -- confirmed via grep before removing. The updated homepage (src/routes/index.tsx) exercises all of this (all four button variants, a card, the type scale, the theme toggle) and was verified by hand in a real running dev server: fetched the rendered HTML, confirmed the shadcn button/card classes and data-slot attributes are present, confirmed the inline theme-detection script runs and toggles the "dark" class correctly, confirmed the print media query and type-scale classes are in the served CSS bundle, and confirmed the old dead classes are gone from the served CSS. Full test suite (19 files / 119 tests) still passes after the change, tsc and eslint are clean. No dark-mode-aware redesign of any other screen exists yet (there's only the one placeholder route to redesign so far) -- this lays the foundation tokens/primitives down for the 24 screens in tab06 to build on, not a finished visual identity for the product. No Storybook or visual regression tooling, and no accessibility audit beyond what shadcn's defaults already provide. Marked In Progress rather than Done since a design system isn't really finished until more than one real screen has exercised it.
A9: M02 | B9: F006 | C9: Email/password + Google sign-in | D9: As a parent I want to sign in securely so that my child's data is private. | E9: better-auth with email+password and Google OAuth; verified email; session cookie httpOnly+secure; logout everywhere. | F9: P0 | G9: M | H9: 2 | I9: S1 | J9: Done | K9: better-auth mounted at /api/auth/$ (catch-all, src/routes/api/auth/$.ts). Email+password with required email verification (verified end-to-end: sign-up -> logged verification link -> verify-email -> sign-in). Google OAuth wired but conditional on GOOGLE_CLIENT_ID/SECRET, which are not set in dev -- needs real credentials before it is testable; the UI has no Google sign-in button yet for the same reason. Session cookie confirmed httpOnly+SameSite=Lax via curl; Secure is added automatically once BETTER_AUTH_URL is https in prod. Sign-out/session endpoints come from betterauth's own router, not hand-written. Resend (M16) does not exist yet, so verification emails are logged server-side, not delivered -- flagged, not silently faked. UI now exists -- see `/` (sign-in/sign-up) and `/onboarding` (add-student wizard), browser-verified end to end including the real email-verification link from the server log.
A10: M02 | B10: F007 | C10: Role model (parent / student / admin) | D10: As a parent I want my child to have a limited login so that they cannot edit marks. | E10: Role stored on user; route guards server-side, not just client; student role cannot access evaluation-override or admin routes. | F10: P0 | G10: M | H10: 3 | I10: S1 | J10: Done | K10: Role stored on users.role (parent/student/admin), assigned server-side only (better-auth additionalFields role/household_id have input:false; a signup payload cannot set them). src/lib/session.ts requireUser/requireRole enforce auth on the request itself. Verified live: unauthenticated request to GET /api/students -> 401; a directly-seeded student-role user -> 403 on GET and POST /api/students. No admin or evaluation-override route exists yet to test T01 literally against, but the same guard is what any future one will use. -- A parent-facing way to actually create a student's login now exists too (POST /api/students/:id/login + a small /onboarding UI) -- this was new scope, not this ticket's own AC, flagged to and approved by the user rather than silently added; see F010's note for the full context.
A11: M02 | B11: F008 | C11: Household & multi-student profiles | D11: As a parent with two children I want separate profiles so that data never mixes. | E11: Household owns N students; student switcher in header; every query scoped by student_id; switching cannot leak cached data. | F11: P0 | G11: M | H11: 3 | I11: S2 | J11: Done | K11: GET/POST /api/students and PATCH /api/students/:id (src/routes/api/students.ts, .../students/.ts), all household-scoped via studentsRepository (F013). Verified live with two separate parent signups: parent B's list is empty and never sees parent A's student; parent B's PATCH on parent A's student returns 404, not 403 or a leaked row. UI now exists -- see `/` (sign-in/sign-up) and `/onboarding` (lists existing students, form to add a new one with name/class/board/school/consent), browser-verified end to end including the real email-verification link from the server log. No student switcher in the header yet though -- that's a separate screen from the onboarding wizard and still doesn't exist. -- A parent-facing way to actually create a student's login now exists too (POST /api/students/:id/login + a small /onboarding UI) -- this was new scope, not this ticket's own AC, flagged to and approved by the user rather than silently added; see F010's note for the full context.
A12: M02 | B12: F009 | C12: Student profile fields | D12: As a coach I want class, board, school and roll number stored so that papers carry the right header. | E12: Profile: name, class, section, roll no, board, school, subjects active, target exam dates; used in paper header automatically. | F12: P0 | G12: S | H12: 1 | I12: S2 | J12: Done | K12: F008's schema already had name/class/section/roll_no/board/school/target_exams -- the real gap was that POST /api/students never accepted section or target_exams at creation, and PATCH /api/students/:id had no target_exams field at all, so a student's target exam dates could never be set or changed after creation (stuck at the hardcoded []). Both routes now accept target_exams as a validated {name, date}[] and POST accepts section too. 'subjects active' is intentionally not modelled: the whole product is single-subject today (CLAUDE.md's launch scope is CBSE Class 7 Maths only, and MATH-SEED is the only subject that has ever existed in this schema), so there is nothing yet for that field to distinguish -- revisit at the tab17 multi-subject rollout, not now. 'used in paper header automatically' already existed before this feature (F033's buildPaperHtml reads student.name/board/class). Verified live against the real dev DB (students-profile.integration.test.ts): create with section+target_exams, a partial PATCH that updates only target_exams without touching other fields, and a rejected malformed date. UI now exists too -- the /onboarding add-student wizard (name/class/board/school/consent checkbox) posts to this same route, browser-verified end to end.
A13: M02 | B13: F010 | C13: Parent-controlled student access | D13: As a parent I want to enable or disable my child's login so that I control screen time. | E13: Toggle per student; disabled student sees a friendly locked screen; parent always retains access. | F13: P2 | G13: S | H13: 1 | I13: S6 | J13: Done | K13: A gap was found while scoping the paper-attempt-start screen: no API or screen anywhere let a parent actually create a student's login -- every test fixture (createStudentSession in db/test-helpers.ts) inserted a student-role user + credential account directly into the database, so a real parent had no path to ever produce a working student login, which blocked the whole "student logs in and attempts a paper" loop from being demonstrable through real UI. This was new scope, not this ticket's own AC -- flagged explicitly per CLAUDE.md's "never invent a feature ID" rule, and the user chose to have it built now, clearly flagged. Closed via a new POST /api/students/:id/login route (parent/admin only, household-scoped, 404 on another household's student, creates a role:'student' user + credential account mirroring the test fixture, links students.user_id, rejects 409 on an existing login or a taken email, never returns the password hash) plus a small /onboarding UI (a "Create login" inline form per student without a user_id; "Login active" shown once one exists). Verified end to end against a real running dev server -- signed up a parent, added a student, created that student's login through the actual request the UI makes, then signed in AS that student account via better-auth's real sign-in and confirmed role='student' and the correct household_id came back -- plus new integration tests (student-login.integration.test.ts: creation works via a real sign-in, double-login rejected, duplicate email rejected) and a new cross-household case added to the T02 sweep (another household's parent gets 404 creating a login for a student she doesn't own). This closes only the creation gap -- F010's actual AC (a toggle to enable/disable an existing student's access, with a friendly locked screen when disabled) is still genuinely not built, so Status stays Not Started.
A14: M03 | B14: F011 | C14: Core schema migration v1 | D14: As a developer I want the schema versioned so that environments stay in sync. | E14: All 26 tables from tab 04 created via numbered migrations; up/down tested; migration runs in CI against a scratch DB. | F14: P0 | G14: L | H14: 5 | I14: S1 | J14: Done | K14: All 32 tables (tab04 lists 32, not 26) created via numbered Kysely migrations against a live Supabase dev project (examprep-ai-dev). Full up/down/up round-trip verified manually. CI workflow (.github/workflows/migrations.yml) verified green on GitHub Actions 2026-09-20 (migrate up, all the way down, back up against a scratch Postgres 17). DB choice: Supabase (Postgres 17), auth stays better-auth per CLAUDE.md — RLS is off pending M20.
A15: M03 | B15: F012 | C15: Seed & fixture data | D15: As a developer I want realistic seed data so that features can be built without manual entry. | E15: Seed loads 1 household, 2 students, 2 subjects, 15 chapters, 60 concepts, 200 questions, 3 historical evaluations. | F15: P0 | G15: M | H15: 2 | I15: S2 | J15: Done | K15: seed.ts now writes exactly the AC's numbers: 15 chapters (2 original + 13 new topic chapters), 60 concepts, 200 questions (all bulk-approved -- short_answer isn't an objective type so F117's tier logic would otherwise leave it in draft with no review-queue UI to approve it from), 2 subjects (MATH-SEED plus a deliberately small SCI-SEED stub -- CLAUDE.md's launch scope is Class 7 Maths only, so the second subject exists to prove multi-subject routes work, not to carry curriculum depth), 1 household with 2 students, and 3 confirmed historical evaluations (40%/80%/60%, via real generatePaper -> attempt -> answer -> submit -> createEvaluation -> confirmEvaluation calls, not hand-inserted rows). All new volume lives under brand-new chapters (chapter_no 3-15) rather than the original chapter 1/2 -- four existing integration test files generate real papers scoped to 'chapter_no=1 of MATH-SEED' and depend on it having exactly their own fixture questions as eligible candidates; adding more approved questions there would have made those tests' random picks nondeterministic. seed.ts also gained an entry-point guard (only auto-runs main() when invoked directly, via pathToFileURL against process.argv[1] -- the Windows-safe pattern already used by the migration runner) so seedBulkFixtures can be called standalone against a DB that already has MATH-SEED, which is exactly how this was verified: run once against the real dev DB, counts confirmed by direct query (15/60/200/2/3), then the full test suite re-run clean (89 tests) to prove the isolation actually holds.
... A20: M04 | B20: F017 | C20: Textbook source registry | D20: As a coach I want each chapter tied to a specific textbook so that NCERT vs Oxford scope differences are respected. | E20: Source record: publisher, title, edition, chapter no, page range, PDF reference; two sources may cover the same topic with different scope. | F20: P0 | G20: M | H20: 2 | I20: S3 | J20: Done | K20: sources table + repository already existed from F011/F013; no additional route needed beyond what chapters already expose (source_id, and chapter creation happens via the skill/seed path per F015's resolution, not a REST endpoint).
A21: M04 | B21: F018 | C21: Concept prerequisite graph | D21: As a system I want concept prerequisites so that remediation can go one level down. | E21: Concept can list prerequisite concept IDs; weak concept surfaces its unmastered prerequisites in the diagnosis. | F21: P2 | G21: M | H21: 3 | I21: S8 | J21: Done
A22: M04 | B22: F019 | C22: Syllabus import from PDF (assisted) | D22: As an admin I want to paste a chapter PDF and get a draft scope so that setup is fast. | E22: Upload chapter PDF, AI proposes concept list + IN/OUT scope, admin edits and approves; nothing saves without approval. | F22: P2 | G22: L | H22: 4 | I22: S10 | J22: Not Started
A23: M05 | B23: F020 | C23: Question CRUD with full metadata | D23: As an admin I want to author questions with all tags so that papers can be assembled by rule. | E23: Fields: concept, bloom, difficulty, marks, type, text, options, answer, hint, step-marks, tags, diagram, language, source; validation per type. | F23: P0 | G23: L | H23: 4 | I23: S3 | J23: Done | K23: POST/GET /api/questions, PATCH /api/questions/:id (admin-only). Question+options+step_marks written as one transaction (src/lib/questions.ts). Type-specific validation via Zod: mcq requires exactly one correct option. Verified live end to end.
A24: M05 | B24: F021 | C24: Step-mark / marking scheme storage | D24: As an evaluator I want stored step marks so that partial credit is consistent. | E24: Marks broken into named steps (e.g. Formula 1, Substitution 1, Answer+unit 1) summing to question marks; enforced by validation. | F24: P0 | G24: M | H24: 3 | I24: S4 | J24: Done | K24: Step marks stored in question_step_marks (F011/F013); creation validates sum(step_marks.marks) === question.marks server-side, verified live (mismatched sum -> 400 with the actual vs expected numbers in the message).
A25: M05 | B25: F022 | C25: Bulk import (CSV / JSON) | D25: As an admin I want to import a question set so that seeding is not manual. | E25: CSV/JSON import with row-level validation report; partial import allowed; rejected rows downloadable with reasons. | F25: P1 | G25: M | H25: 2 | I25: S4 | J25: Done | K25: POST /api/questions/bulk-import (tab05's exact route, Admin, multipart file field, format inferred from the filename extension unless overridden). Extracted the single-question validation (previously inline in POST /api/questions) into a shared questionInputSchema (src/lib/questions.ts) so one question is never valid by different rules depending on which route it came through. Each row -- CSV via papaparse, JSON via a plain array -- is validated and inserted independently through the same schema + createQuestion(), so one bad row never blocks the rest ('partial import allowed'); the JSON response's per-row {row, status, question_id | errors} is the 'rejected rows with reasons' report itself, not a separate download artifact. CSV supports the common case only -- mcq/fill_blank/short_answer with up to 4 lettered options via option_a_text/option_a_correct-style columns -- since CSV can't naturally represent step_marks or open-ended option counts; JSON is the richer path for those. Verified live against the real dev DB: a 2-row CSV (1 valid mcq, 1 missing its answer) imports the valid row and reports the invalid one with a concept-specific error message, a JSON import does the same, and admin-only access is enforced. Full suite green (102 tests).
A26: M05 | B26: F023 | C26: Duplicate & near-duplicate detection | D26: As an admin I want duplicates flagged so that a paper never repeats a question. | E26: Exact-hash plus embedding similarity check on save; >0.9 similarity warns with a link to the existing question. | F26: P1 | G26: M | H26: 3 | I26: S5 | J26: In Progress | K26: Exact-hash half only -- the embedding-similarity half of the AC needs an AI embeddings provider, and no ANTHROPIC_API_KEY (or any provider) is configured. Migration 0042 adds questions.text_hash (sha256 of lowercased, whitespace-collapsed text), backfilled in JS using the exact same computeTextHash() new inserts use (not a separately-written SQL equivalent, which risks silently diverging from the real algorithm), indexed per concept. createQuestion() now looks up an existing, non-retired question in the same concept with the same hash before inserting, and returns duplicate_of:{id,text} rather than blocking the save -- 'warns with a link to the existing question', not a hard stop. Wired through both POST /api/questions and F022's bulk import (each row's result). Scoped per-concept, not global: the same worked example can legitimately appear under two different concepts. Verified live against the real dev DB: an exact match (including a case/whitespace variant) in the same concept is flagged, the same text under a different concept is not, and a genuinely new question isn't flagged. Also cleaned up orphaned rows left behind by an unrelated Vitest worker crash during this same session (a one-off infra fluke, confirmed non-reproducible across two clean re-runs) -- unrelated to this feature but caught while verifying it. Full suite green (105 tests). Marked In Progress: the similarity-based near-duplicate half of the AC isn't built.
A27: M05 | B27: F024 | C27: Diagram & figure support | D27: As an author I want diagram questions so that geometry and biology are testable. | E27: Diagram type + parameters render as SVG (intersecting lines, transversal, number line, place-value, circuit, ray diagram); prints cleanly. | F27: P1 | G27: L | H27: 4 | I27: S5 | J27: Done
A28: M05 | B28: F025 | C28: AI question generation with review queue | D28: As an admin I want AI to draft questions so that the bank grows quickly. | E28: Generate N questions for a concept at a given Bloom/difficulty; output lands in review queue as Draft; only approved questions enter papers. | F28: P1 | G28: L | H28: 4 | I28: S6 | J28: Done | K28: New POST /api/questions/generate (tab05's exact route) implements AI-01: takes concept_id/count/bloom/difficulty, loads the concept plus its chapter's chapter_scope (IN/OUT), and prompts a strong model with the concept's idea/rule/example, the real IN-scope item list, the real OUT-scope list, and up to 3 approved same-concept/bloom/difficulty exemplars for style. Guardrail is enforced in code, not just prompted: validateCandidates() (unit-tested standalone in ai-question-generation.test.ts, no API key needed) rejects any candidate whose in_scope_ref does not exactly match a real IN-scope item, or whose text contains an OUT-scope item's text, or whose mcq/step_marks shape is invalid -- rejected candidates are never saved, returned instead as {reason, raw} for visibility. Migration 0044 adds questions.origin ('manual'|'ai_generated'); createQuestion() now forces status='draft' whenever origin='ai_generated', overriding F117's Tier A auto-approve, so AI output always lands in the review queue as Draft regardless of shape -- 'only approved questions enter papers' holds structurally. 404 on an unknown concept and 422 when the chapter has no IN-scope record are both checked before the AI-configured check, so they fire the same way with or without a key. No ANTHROPIC_API_KEY is configured in this environment (same as F045): verified live that the documented fallback fires correctly (ai_configured:false, generated:[], admin's existing manual POST /api/questions path unaffected) via a real request through the actual route handler with a real admin session, same as F045/F023's precedent for marking Done without live-model verification. Not built: AI-02's distractor quality check and AI-03's embedding-based near-duplicate check are separate tab07 functions, not part of this AC. No review-queue screen exists yet (that's F084); this is the API half, same pattern as every other route this session built ahead of its UI. Full suite green (139 tests, up from 129), tsc/eslint clean. [2026-09-17 UPDATE] The Draft-then-review behaviour for AI-generated output was removed along with F117/F084 (migration 0061_remove_question_approval_workflow) -- createQuestion() no longer forces status='draft' for origin='ai_generated'; every generated question is approved and immediately eligible for papers. 'Only approved questions enter papers' still holds (trivially, since nothing is ever anything else), but there is no longer a human review step between generation and use.
A29: M05 | B29: F026 | C29: Question usage history | D29: As a system I want to know when a question was last served so that recent repeats are avoided. | E29: Per student, last_served_at and times_served; generator excludes questions served within a configurable window. | F29: P1 | G29: S | H29: 1 | I29: S6 | J29: Done | K29: The exclusion mechanic already existed (generatePaper's recentUsageWindowDays, default 14 days) but was only reachable by calling generatePaper() directly -- every test in this repo does that, but the real POST /api/papers/generate route never exposed it, so 'configurable window' wasn't actually true for a real caller. Added recent_usage_window_days to the route's schema (nonnegative int, passed through as-is). Added questionUsageRepository.summaryForStudent() (last_served_at via MAX(served_at), times_served via COUNT, grouped per question) and wired it into GET /api/questions via an opt-in student_id query param -- usage is meaningless without a specific student to ask about, so it's additive/opt-in rather than always joined. Verified live against the real dev DB with a fixture sized to make the window's effect directly observable (exactly one eligible question): first generation uses it, a second generation with the default window hits a shortfall (correctly excluded), and recent_usage_window_days:0 makes it eligible again through the real route -- then GET /api/questions?student_id=... reports times_served:2. Full suite green (109 tests).
A30: M06 | B30: F027 | C30: Blueprint definition engine | D30: As a coach I want the school's real paper pattern stored so that mocks match the exam. | E30: Blueprint: sections with name, question count, marks each, type mix, Bloom mix, choice rules, word limits; a blueprint is data, not code. | F30: P0 | G30: L | H30: 5 | I30: S6 | J30: Done | K30: GET/POST /api/blueprints (admin-only POST), sections/bloom_targets/choice_rules as jsonb. total_marks is server-derived from sections, not client-supplied. choice_rules is accepted and stored but not used by the generator (F030 deferred). Verified live: non-admin POST -> 403, admin POST -> 201 with correct derived total_marks. The /generate screen (built after this ticket) now drives this via a real UI -- student/blueprint/chapter pickers, shortfalls rendered to the parent, browser-verified end to end against a live dev server (a fresh sign-up, add a student, generate a paper, confirm the shortfall list renders when the seed question bank can't fill a slot).
A31: M06 | B31: F028 | C31: Weighted concept selection (40/40/20) | D31: As a coach I want papers to over-test weak concepts so that practice is targeted. | E31: Selection draws 40% from WEAK/PRIORITY, 40% NEEDS PRACTICE, 20% STRONG per the tracker; actual distribution is shown to the parent. | F31: P0 | G31: L | H31: 4 | I31: S6 | J31: Done | K31: src/lib/papers.ts generatePaper() buckets concepts into weak+priority / needs-practice / strong per the student's concept_status (no-status concepts default to needs-practice) and apportions each section's slots 40/40/20 via largest-remainder rounding so counts always sum exactly. Actual achieved bucket mix is written to papers.weighting.actual. Verified live end to end with a real weak/neutral/strong concept fixture -- correct per-bucket question counts, including a supply-constrained run that exercised partial fulfilment correctly. The /generate screen (built after this ticket) now drives this via a real UI -- student/blueprint/chapter pickers, shortfalls rendered to the parent, browser-verified end to end against a live dev server (a fresh sign-up, add a student, generate a paper, confirm the shortfall list renders when the seed question bank can't fill a slot).
A32: M06 | B32: F029 | C32: Bloom & difficulty balancing | D32: As a coach I want the cognitive mix honoured so that papers are not all recall. | E32: Generator satisfies the blueprint's Bloom targets within +/-5 percentage points, or reports why it could not. | F32: P0 | G32: M | H32: 3 | I32: S7 | J32: Done | K32: Actual Bloom mix is computed post-selection and compared to blueprint.bloom_targets; any Bloom level off by more than 5 percentage points is appended to papers.shortfalls with the actual vs target numbers, verified live in the supply-constrained test run (correctly flagged both a 12pp Remember and 12pp Understand deviation once shortfalls skewed the mix). The /generate screen (built after this ticket) now drives this via a real UI -- student/blueprint/chapter pickers, shortfalls rendered to the parent, browser-verified end to end against a live dev server (a fresh sign-up, add a student, generate a paper, confirm the shortfall list renders when the seed question bank can't fill a slot).
A33: M06 | B33: F030 | C33: Internal choice (OR) handling | D33: As a student I want internal choice so that the paper matches the board pattern. | E33: Choice pairs marked in the paper, counted once in total marks, and handled correctly in evaluation and coverage stats. | F33: P1 | G33: M | H33: 2 | I33: S7 | J33: Done
A34: M06 | B34: F031 | C34: Manual paper builder | D34: As a coach I want to swap a question so that I retain final control. | E34: Drag/replace a selected question; regenerate a single slot; lock questions before regenerating the rest. | F34: P1 | G34: M | H34: 3 | I34: S7 | J34: Done | K34: POST /api/papers/:id/regenerate-slot swaps one slot in place (same concept/bloom/marks as the slot being replaced, excluding every question already used in that paper) without touching any other paper_questions row -- 'lock others' is inherent since only the named slot is ever updated. Verified live: regenerated a slot to a different question of the same shape, and confirmed cross-household denial (404). Drag-and-drop UI obviously doesn't exist -- no screens exist in this repo at all -- this is the API half only.
A35: M06 | B35: F032 | C35: Coverage guard & shortfall reporting | D35: As a coach I want to know when the bank cannot fill a blueprint so that I am not given a silently weak paper. | E35: If a slot cannot be filled, the paper is still produced with an explicit shortfall note naming the concept and slot. | F35: P0 | G35: S | H35: 2 | I35: S7 | J35: Done | K35: Unfillable slots do not block generation -- the paper is produced with a shortfalls entry naming the exact section, bucket, and constraint (bloom/difficulty/marks) that had no eligible approved question. Verified live: a deliberately undersupplied fixture (1 eligible question per bucket where 2 were needed) generated a 6-question paper instead of erroring, with 2 shortfall entries pinpointing exactly which slots came up short. The /generate screen (built after this ticket) now drives this via a real UI -- student/blueprint/chapter pickers, shortfalls rendered to the parent, browser-verified end to end against a live dev server (a fresh sign-up, add a student, generate a paper, confirm the shortfall list renders when the seed question bank can't fill a slot).
A36: M07 | B36: F033 | C36: Print-exact A4 PDF renderer | D36: As a parent I want a printable paper so that my child writes it like a real exam. | E36: Server-side HTML to PDF, A4, correct margins, page breaks never split a question, printBackground on, embedded fonts. | F36: P0 | G36: L | H36: 5 | I36: S8 | J36: Done | K36: GET /api/papers/:id/pdf (tab05's exact contract: Parent role, theme + include_key query params, application/pdf stream) renders the paper via Playwright/headless Chromium (tab09's locked choice, now actually installed -- playwright + a downloaded Chromium build). A4 via page.pdf()'s margin option, printBackground:true, page-break-inside:avoid on every question block so a question is never split across a page. Embedded fonts happen automatically -- Chromium's PDF export always subsets and embeds whatever font the page actually renders with (Georgia here). theme is accepted per the contract but not yet acted on since no theme packs exist (F034/F120 Not Started) -- every request renders the one 'Plain' layout. Verified live: generated a real PDF against the real dev DB (src/routes/papers-pdf.integration.test.ts), confirmed the %PDF- magic header, a realistic byte size, and (via a manual screenshot render, not committed) that the layout actually looks like an exam paper -- header, sectioned questions, numbered continuously across sections, marks in brackets.
A37: M07 | B37: F034 | C37: Paper theme templates | D37: As a student I want an appealing paper so that practice feels less dull. | E37: At least two themes (plain school format, illustrated/comic format) selectable at generation; both print in black-and-white legibly. | F37: P1 | G37: M | H37: 3 | I37: S8 | J37: Done
A38: M07 | B38: F035 | C38: Rough-work column & answer space | D38: As a coach I want a printed rough-work column so that working is separated from the answer. | E38: Every working page carries a narrow ruled rough column, ruled answer panels sized to the marks, and a labelled draw-here box for diagrams. | F38: P0 | G38: M | H38: 2 | I38: S8 | J38: Done | K38: Built into the same paper-template.ts used by F033's route: a 16mm ruled rough-work column pinned with position:fixed so it repeats on every printed page (Chromium's standard trick, since @page margin boxes aren't supported), ruled answer-line panels sized to the question's marks (short_answer/long_answer scale with marks; fill_blank gets one line; mcq/assertion_reason/match/multi_statement get an options list instead), and a labelled 'Draw here' box whenever a question's diagram_kind is set, regardless of its base type. Not print-QA'd on a real printer/multiple devices (F107 Not Started) -- verified only via a rendered PDF/screenshot in this dev environment.
A39: M07 | B39: F036 | C39: Answer key + marking scheme export | D39: As a parent I want the key separately so that I can mark without seeing it beforehand. | E39: Separate PDF: answers, step-wise marks, expected diagram description; never bundled into the student paper file. | F39: P0 | G39: M | H39: 2 | I39: S8 | J39: Done | K39: The same GET /api/papers/:id/pdf route (tab05 defines one route with an include_key boolean, not two separate paths) renders the answer key + step-wise marks + expected diagram description as a distinct trailing section (its own page-break-before, never interleaved with the paper's questions) when include_key=true -- and this branch is only ever reachable by the parent/admin-only route, so a student session can never produce or receive it, satisfying the hard rule structurally, not just by convention. Verified live: the include_key=true response is a strictly larger PDF with more pages than the default response (src/routes/papers-pdf.integration.test.ts), and a correct-option-letter test question round-trips through the key with the right label.
A40: M07 | B40: F037 | C40: Concept coverage & Bloom table | D40: As a coach I want the coverage table so that I can verify what the paper actually tested. | E40: Auto table: concept, questions, marks, % weight, Bloom split; appended to the key, also shown on screen. | F40: P0 | G40: S | H40: 2 | I40: S8 | J40: Done | K40: computeCoverageTable() (src/lib/pdf/coverage.ts) computes concept/questions/marks/%weight/Bloom-split per concept actually used on a paper. It's appended to the answer-key PDF (F036) and also served standalone as JSON at GET /api/papers/:id/coverage (tab05's exact route) -- the 'shown on screen' half of the AC has real data to call now, even though no screen exists anywhere in this repo (M14 dashboards are all Not Started). Verified live against the real dev DB with a 2-question, 2-Bloom-level fixture.
A41: M07 | B41: F038 | C41: Paper library & versioning | D41: As a parent I want past papers stored so that I can reprint or compare. | E41: Every generated paper persisted with its question IDs and blueprint version; re-download reproduces the identical PDF. | F41: P1 | G41: M | H41: 2 | I41: S9 | J41: Done | K41: "Every generated paper persisted with its question IDs" was already true (F011's schema: paper_questions rows are never touched once written, per the 'nothing is deleted' invariant). The real gap was 'blueprint version' -- papers stored only a live blueprint_id FK, so if a blueprint were ever edited in place, an old paper's notion of 'its blueprint' would silently mean whatever the blueprint looks like today. Migration 0041 adds papers.blueprint_version, backfilled from each existing paper's current blueprint.version (defaults to 1 for any future direct insert that doesn't specify one, matching blueprints.version's own default), and generatePaper() now snapshots it at generation time. No blueprint edit route exists yet (tab05 only lists POST /api/blueprints, no PATCH), so this was a forward-looking fix, not an active bug. 'Re-download reproduces the identical PDF' verified live via GET /api/papers/:id/pdf called twice against the real dev DB: identical page count and near-identical byte size -- not byte-for-byte identical, since Chromium stamps a fresh /CreationDate into every PDF export with no Playwright option to override it, so 'identical' here means identical rendered content, not an exact byte match. Full suite green (97 tests).
A42: M08 | B42: F039 | C42: Timed attempt runner | D42: As a student I want a timer so that I practise exam pacing. | E42: Countdown per paper duration, visible section navigator, warning at 10 minutes, auto-submit at zero with all saved answers. | F42: P0 | G42: L | H42: 4 | I42: S9 | J42: Done | K42: Server side only: POST /api/attempts records a server-side started_at, and POST /api/attempts/:id/submit computes duration_used_sec from it -- this is the honest server half of the AC. Countdown UI, visible section navigator, 10-minute warning, and genuine auto-submit-at-zero all need a client timer or a background job; none exist. No screens exist anywhere in this repo, and no background-job infra is installed (tab09 names Inngest/Trigger.dev, neither chosen). The screen now exists (src/routes/attempt/$id.tsx): a client-side countdown computed from paper.duration_min and attempt.started_at (server truth, so it survives refresh) and section navigation as jump links grouped by paper_questions.section. Still missing the AC's 10-minute warning and genuine auto-submit-at-zero -- the client only swaps the clock's text to "Time's up" once remaining time hits zero and never calls submit itself; no background job exists to enforce this server-side either, so the attempt just sits open past the deadline until the student submits by hand. Verified live end to end as part of the same run described under F040's note.
A43: M08 | B43: F040 | C43: Autosave & resume | D43: As a student I want my answers saved so that a lost connection does not lose my work. | E43: Answer saved within 2s of change and on blur; refresh or device change resumes at the same question with the timer intact. | F43: P0 | G43: M | H43: 3 | I43: S9 | J43: Done | K43: PATCH /api/attempts/:id/answer is the autosave endpoint itself -- one upsert per call on the (attempt_id, paper_question_id) unique constraint from F011, verified live. The "within 2s" debounce and "resume at the same question" are client behaviour; the server makes resume possible (GET /api/papers/:id + the saved attempt_answers already give a client everything needed to restore state) but no client exists to do it. A client now exists (src/routes/attempt/$id.tsx): each answer edit is saved via a 600ms debounce calling this same PATCH /answer endpoint -- not literally "within 2s of change and on blur" since there is no separate blur handler, just the debounce, but comfortably under the 2s bar. Resume is real for answers: a new GET /api/attempts/:id endpoint (src/routes/api/attempts/$id.ts) returns the attempt, paper header, and every question with any previously-saved answer, and the screen pre-fills its state from that on load -- verified live (saved an answer, re-fetched, got it back). "Resumes at the same question" doesn't strictly apply to this screen's layout, since every question renders on one page with section jump links rather than one question at a time, so there is no single "current question" position to restore; the timer stays intact across reload because it is recomputed from the server's started_at rather than kept client-side. This GET endpoint deliberately builds its own narrow response projection instead of reusing paperQuestionsRepository.listForPaperWithQuestions / questionOptionsRepository.listByQuestion directly, because those select questions.answer and is_correct for grading elsewhere -- this is the one place in the product where the "student can never see an answer key" rule (T09) is load-bearing at the wire level, and it has its own dedicated integration tests (src/routes/attempt-detail.integration.test.ts, 4 tests covering the missing answer key, is_correct flags, resume state, and cross-student 404) plus a cross-household case added to the T02 sweep (src/routes/cross-household-access.integration.test.ts).
A44: M08 | B44: F041 | C44: Per-question time capture | D44: As a coach I want time per question so that pacing problems are visible. | E44: Seconds spent per question recorded; report flags questions consuming >2x their mark-proportional time budget. | F44: P1 | G44: M | H44: 2 | I44: S10 | J44: Done | K44: time_spent_sec is accepted and stored per answer via PATCH /api/attempts/:id/answer (verified live). The pacing-anomaly report ('flags questions consuming >2x their mark-proportional time budget') is not built -- that is an analysis/reporting endpoint over this data, not storage, and no such route is listed in tab05. The new /attempt/:id screen (src/routes/attempt/$id.tsx) does not send time_spent_sec on any answer save -- its autosave call only ever posts paper_question_id plus selected_option/response_text, so this field is still never populated by a real client despite the storage and endpoint support already existing. No progress on the pacing-anomaly report either.
A45: M08 | B45: F042 | C45: Answer input types | D45: As a student I want the right input per question type so that answering is natural. | E45: MCQ radio, fill-in text, true/false, short answer textarea, long answer rich text; math input helper for symbols and fractions. | F45: P0 | G45: M | H45: 3 | I45: S9 | J45: Done | K45: Schema already carries whatever shape each type needs (attempt_answers.response_text / selected_option); the PATCH /answer endpoint accepts both generically and does not care which input widget produced them. Radio/textarea/rich-text/math-symbol widgets are UI components -- not applicable without screens. The screen now exists (src/routes/attempt/$id.tsx) but only implements two of the five listed widgets: real MCQ radio buttons rendered from the question's actual options, and a single generic textarea used for every non-mcq type alike -- fill-in, true/false, short answer, and long answer all get the same plain textarea, with no true/false-specific control, no rich text editor for long answers, and no math input helper for symbols or fractions. AC still only partially met.
...

Sheet 04 Data Model
A1: 04 Data Model — 26 core tables. Build and migrate this before any UI work.
A3: Table | B3: Purpose | C3: Key Columns | D3: Relations | E3: Module
A4: households | B4: Tenant root. One family or one tutor. | C4: id, name, owner_user_id, plan, created_at | D4: -> users, students | E4: M02/M03
A5: users | B5: Anyone who signs in. | C5: id, household_id, email, name, role(parent|student|admin), auth_provider, is_active | D5: -> households | E5: M02
A6: students | B6: The learner profile papers are generated for. | C6: id, household_id, user_id(nullable), name, class, section, roll_no, board, school, target_exams(jsonb) | D6: -> households | E6: M02
A7: subjects | B7: Subject per board and class. | C7: id, board, class, name, code, language, is_active | D7: -> chapters | E7: M04
A8: sources | B8: Textbook a chapter comes from. | C8: id, subject_id, publisher, title, edition, year, file_ref, notes | D8: -> chapters | E8: M04
